Workbook
Name DemoCode: 'A3 Exercise'!$B$139
Name DemoDrop: 'B1 Exercise'!$B$156
Name DemoPeople: 'A3 Exercise'!$B$192
Name Exer1: 'B1 Exercise'!$B$14
Name Exer1: 'A3 Exercise'!$B$13
Name Exer2: 'B1 Exercise'!$B$37
Name Exer2: 'A3 Exercise'!$B$37
Name Exer3: 'B1 Exercise'!$B$59
Name Exer3: 'A3 Exercise'!$B$62
Name Exer4: 'B1 Exercise'!$B$103
Name Exer4: 'A3 Exercise'!$B$87
Name Exer5: 'B1 Exercise'!$B$138
Name Exer5: 'A3 Exercise'!$B$112
Name HowTo: 'B1 Instructions'!$B$24
Name HowTo: 'B1 Instructions'!$B$24
Name HowTo: 'A3 Instructions'!$B$25
Name ImportantNotes: 'B1 Instructions'!$B$78
Name ImportantNotes: 'B1 Instructions'!$B$78
Name ImportantNotes: 'A3 Instructions'!$B$53
Name mult: 'B1 Instructions'!$B$118
Name OneCol: 'A4 Instructions'!$B$36
Name OneCol: #REF!
Name Prerequesite: 'B1 Instructions'!$B$66
Name Prerequesite: 'B1 Instructions'!$B$66
Name Prerequesite: 'A3 Instructions'!$B$46
Name Reset: 'A4 Instructions'!#REF!
Name Reset: #REF!
Name ResetEx: 'A4 Instructions'!$B$65
Name ThePoint: 'B1 Instructions'!$B$3
Name ThePoint: 'B1 Instructions'!$B$3
Name ThePoint: 'A3 Instructions'!#REF!
Name Top: 'B1 Instructions'!$B$2
Name Top: 'B1 Instructions'!$B$2
Name Top: 'A3 Instructions'!#REF!
Name TopExercise: 'B1 Exercise'!$B$3
Name TopExercise: 'A3 Exercise'!$B$3
Name TwoCol: 'A4 Instructions'!$B$23
Name TwoCol: #REF!
Name Versus: 'B1 Instructions'!$B$130
Name wildcards: 'B1 Instructions'!$B$81

Sheet Excel Magic
E2: Dazzle with Data Using Excel Magic!
E3: Created by Julie Marcoux, Dalhousie University
E6: JUMP TO MAIN MENU
E9: CONTACT INFORMATION
E10: Last updated June 9, 2026
E12: This file is shared under CC BY-NC 4.0

Sheet Menu
E1: Return to Dazzling Title Screen
E3: Welcome to a workshop in which you will be amazed with Excel magic tricks.
E4: But don't worry, most of the tricks will be revealed!
E5: You too can become an Excel expert!
E7: SECTION A - Let's start with easy tricks that only require clicking around
C8: A1 | E8: You guys know about "paste as values" already, right? Everyone?
E9: "Go to special" time! We're going to color all empty cells in the worksheet! | G9: A2
C10: A3 | E10: We'll be done with "Flash fill" in a flash!
E11: We'll build a list of unique values by eliminating duplicates. | G11: A4
C12: A5 | E12: We're going to learn about my favorite Find/Replace tricks.
E15: SECTION B - Let's have fun with some formulas!
C16: B1 | E16: Let's take a look at XLOOKUP!
E17: Did you think we were going to forget about OR and AND? As IF! | G17: B2
C18: B3 | E18: We're going to COUNT from A to Z!
E19: We'll use our list of unique values and SumIf and SumIfs to do some magic! | G19: B4
E22: SECTION C - It's… too much! Have a look at some leftover features and formulas!
C23: C1 | E23: Let's concentrate on concatenation
E24: We'll take a quick look at LEFT, MID, RIGHT, and FIND. | G24: C2
C25: C3 | E25: Let's take a look at VLOOKUP!
E26: We're going to witness the power of CSE formulas. | G26: C4
E29: Need More Help?

Sheet A1 Instructions
A1: * | B1: Main Menu | C1: Exercise | D1: Data worksheet
C3: A1 PASTE AS VALUES
C5: What are we doing here?
C6: I'm making extra sure you know about Paste Special.
C7: It is SUCH a useful thing to know.
C8: I mostly use it to transform formulas into data.
C10: This is amazing! What if I want to do more?
C11: I guess you could explore the different options in the 'Paste Special' menu?
C13: How do I get started again?
C14: The example is ready to go, just keep reading!
C15: If you need a reset, copy-paste from the bottom of this worksheet
C16: Use the "Paste as values" button for copy-pasting as data.
A19: * | B19: INSTRUCTIONS
B20: Select cells containing formulas and copy them using your favorite method.
B21: Then click on the arrow under "Paste" in the "Home" ribbon and select one of the options as appropriate.
B23: If you don't quite understand what happens below in the example, reinitialize it by copy pasting the data and formulas at the bottom of the spreadsheet.
B24: Click on C32 and look at the formula bar. Copy paste C32 to C37 in the worksheet and see what happens. C32 and C37 should be different.
B25: Click on C32 again and copy it. In the "Clipboard" section of the "Home" ribbon, click on the dropdown arrow under "Paste".
B26: Without moving, select the first option under "Paste values".
B27: Click on C32 again and look at the formula bar. Copy-paste C32 to C37 and see what happens. C32 and C37 should be identical.
B29: Alternatively, go to the "Formulas" ribbon and click on "Show Formulas" in the "Formula Auditing" section.
A31: * | B31: Data | C31: Steps | Formulas
B32: I'm using | C32: =B32&" "&B33&". " &B34&" "&B35 -> I'm using concatenation. Let's transform that into values.
B33: concatenation | C33: =B36&" "&B37 -> Try copying in place and pasting as values.
B34: Let's transform that | C34: =B38&" "&B39&" "&B40&" "&B41&" "&B42 -> See what happens when you copy-paste from the formulas column before and after doing the paste as values.
B35: into values.
B36: Try copying in place
B37: and pasting as values.
B38: See what happens when
B39: you copy-paste
B40: from the formulas column
B41: before and after
B42: doing the paste as values.
A45: * | B45: RESET EXAMPLE
B47: I'm using | C47: =B47&" "&B48&". " &B49&" "&B50 -> I'm using concatenation. Let's transform that into values.
B48: concatenation | C48: =B51&" "&B52 -> Try copying in place and pasting as values.
B49: Let's transform that | C49: =B53&" "&B54&" "&B55&" "&B56&" "&B57 -> See what happens when you copy-paste from the formulas column before and after doing the paste as values.
B50: into values.
B51: Try copying in place
B52: and pasting as values.
...

Sheet A1 Exercise
A1: * | B1: Main Menu | C1: Instructions | D1: Data worksheet
A3: * | B3: PASTE AS VALUES EXERCISE
B4: OH NO! Someone has directly referenced data from the 2021 CSD worksheet in this worksheet.
B5: This displeases you, for some reason. Perhaps you are afraid of what will happen if you decide to delete the data worksheet?
B6: You are right to be afraid, if ANYTHING happens to 2021 CSD, then this entire worksheet stops working.
B8: For extra security, you decide to transform all the formulas in this worksheet as values, except for the 15+ population total.
B9: Start by previewing formulas by clicking on "Show Formulas" in the "Formula Auditing" section of the "Formulas" ribbon
B10: then turn off "Show Formulas". Transform the formulas in the table into values, skipping the formula that sums up the population total.
B11: You can check your work by clicking on "Show Formulas" in the "Formula Auditing" section of the "Formulas" ribbon.
A13: * | B13: Table to copy-paste as value | G13: Did it work?
B14: ='2021 CSD'!A1 -> Province | C14: ='2021 CSD'!D1 -> SUBDIV Name | D14: ='2021 CSD'!E1 -> Tot Pop 2021 | E14: Prov - County - TotPop | G14: Was the formula removed?
B15: ='2021 CSD'!A2 -> 12 | C15: ='2021 CSD'!D2 -> Barrington | D15: ='2021 CSD'!E2 -> 6523 | E15: ="NS-"&C15&"-"&D15 -> NS-Barrington-6523 | G15: =IF(OR(_xlfn.ISFORMULA(B15),_xlfn.ISFORMULA(C15),_xlfn.ISFORMULA(D15),_xlfn.ISFORMULA(E15)),"Try again","YAY!") -> Try again | H15: <-You want formulas on this row of the table removed
B16: ='2021 CSD'!A3 -> 12 | C16: ='2021 CSD'!D3 -> Clark's Harbour | D16: ='2021 CSD'!E3 -> 725 | E16: ="NS-"&C16&"-"&D16 -> NS-Clark's Harbour-725 | G16: =IF(OR(_xlfn.ISFORMULA(B16),_xlfn.ISFORMULA(C16),_xlfn.ISFORMULA(D16),_xlfn.ISFORMULA(E16)),"Try again","YAY!") -> Try again | H16: <-You want formulas on this row of the table removed
B17: ='2021 CSD'!A4 -> 12 | C17: ='2021 CSD'!D4 -> Shelburne | D17: ='2021 CSD'!E4 -> 4336 | E17: ="NS-"&C17&"-"&D17 -> NS-Shelburne-4336 | G17: =IF(OR(_xlfn.ISFORMULA(B17),_xlfn.ISFORMULA(C17),_xlfn.ISFORMULA(D17),_xlfn.ISFORMULA(E17)),"Try again","YAY!") -> Try again | H17: <-You want formulas on this row of the table removed
B18: ='2021 CSD'!A5 -> 12 | C18: ='2021 CSD'!D5 -> Shelburne | D18: ='2021 CSD'!E5 -> 1644 | E18: ="NS-"&C18&"-"&D18 -> NS-Shelburne-1644 | G18: =IF(OR(_xlfn.ISFORMULA(B18),_xlfn.ISFORMULA(C18),_xlfn.ISFORMULA(D18),_xlfn.ISFORMULA(E18)),"Try again","YAY!") -> Try again | H18: <-You want formulas on this row of the table removed
B19: ='2021 CSD'!A6 -> 12 | C19: ='2021 CSD'!D6 -> Lockeport | D19: ='2021 CSD'!E6 -> 476 | E19: ="NS-"&C19&"-"&D19 -> NS-Lockeport-476 | G19: =IF(OR(_xlfn.ISFORMULA(B19),_xlfn.ISFORMULA(C19),_xlfn.ISFORMULA(D19),_xlfn.ISFORMULA(E19)),"Try again","YAY!") -> Try again | H19: <-You want formulas on this row of the table removed
B20: ='2021 CSD'!A7 -> 12 | C20: ='2021 CSD'!D7 -> Argyle | D20: ='2021 CSD'!E7 -> 7870 | E20: ="NS-"&C20&"-"&D20 -> NS-Argyle-7870 | G20: =IF(OR(_xlfn.ISFORMULA(B20),_xlfn.ISFORMULA(C20),_xlfn.ISFORMULA(D20),_xlfn.ISFORMULA(E20)),"Try again","YAY!") -> Try again | H20: <-You want formulas on this row of the table removed
B21: ='2021 CSD'!A8 -> 12 | C21: ='2021 CSD'!D8 -> Yarmouth | D21: ='2021 CSD'!E8 -> 10067 | E21: ="NS-"&C21&"-"&D21 -> NS-Yarmouth-10067 | G21: =IF(OR(_xlfn.ISFORMULA(B21),_xlfn.ISFORMULA(C21),_xlfn.ISFORMULA(D21),_xlfn.ISFORMULA(E21)),"Try again","YAY!") -> Try again | H21: <-You want formulas on this row of the table removed
B22: ='2021 CSD'!A9 -> 12 | C22: ='2021 CSD'!D9 -> Yarmouth | D22: ='2021 CSD'!E9 -> 6829 | E22: ="NS-"&C22&"-"&D22 -> NS-Yarmouth-6829 | G22: =IF(OR(_xlfn.ISFORMULA(B22),_xlfn.ISFORMULA(C22),_xlfn.ISFORMULA(D22),_xlfn.ISFORMULA(E22)),"Try again","YAY!") -> Try again | H22: <-You want formulas on this row of the table removed
B23: ='2021 CSD'!A10 -> 12 | C23: ='2021 CSD'!D10 -> Yarmouth 33 | D23: ='2021 CSD'!E10 -> 181 | E23: ="NS-"&C23&"-"&D23 -> NS-Yarmouth 33-181 | G23: =IF(OR(_xlfn.ISFORMULA(B23),_xlfn.ISFORMULA(C23),_xlfn.ISFORMULA(D23),_xlfn.ISFORMULA(E23)),"Try again","YAY!") -> Try again | H23: <-You want formulas on this row of the table removed
B24: ='2021 CSD'!A11 -> 12 | C24: ='2021 CSD'!D11 -> Clare | D24: ='2021 CSD'!E11 -> 7678 | E24: ="NS-"&C24&"-"&D24 -> NS-Clare-7678 | G24: =IF(OR(_xlfn.ISFORMULA(B24),_xlfn.ISFORMULA(C24),_xlfn.ISFORMULA(D24),_xlfn.ISFORMULA(E24)),"Try again","YAY!") -> Try again | H24: <-You want formulas on this row of the table removed
B25: ='2021 CSD'!A12 -> 12 | C25: ='2021 CSD'!D12 -> Digby | D25: ='2021 CSD'!E12 -> 7242 | E25: ="NS-"&C25&"-"&D25 -> NS-Digby-7242 | G25: =IF(OR(_xlfn.ISFORMULA(B25),_xlfn.ISFORMULA(C25),_xlfn.ISFORMULA(D25),_xlfn.ISFORMULA(E25)),"Try again","YAY!") -> Try again | H25: <-You want formulas on this row of the table removed
B26: ='2021 CSD'!A13 -> 12 | C26: ='2021 CSD'!D13 -> Digby | D26: ='2021 CSD'!E13 -> 2001 | E26: ="NS-"&C26&"-"&D26 -> NS-Digby-2001 | G26: =IF(OR(_xlfn.ISFORMULA(B26),_xlfn.ISFORMULA(C26),_xlfn.ISFORMULA(D26),_xlfn.ISFORMULA(E26)),"Try again","YAY!") -> Try again | H26: <-You want formulas on this row of the table removed
B27: ='2021 CSD'!A14 -> 12 | C27: ='2021 CSD'!D14 -> Bear River (Part) 6 | D27: ='2021 CSD'!E14 -> 141 | E27: ="NS-"&C27&"-"&D27 -> NS-Bear River (Part) 6-141 | G27: =IF(OR(_xlfn.ISFORMULA(B27),_xlfn.ISFORMULA(C27),_xlfn.ISFORMULA(D27),_xlfn.ISFORMULA(E27)),"Try again","YAY!") -> Try again | H27: <-You want formulas on this row of the table removed
C28: Total population: | D28: =SUM(D15:D27) -> 55713 | G28: =IF(_xlfn.ISFORMULA(D28),"YAY!","Oh no!") -> YAY! | H28: <-You want to keep the formula on this row of the table

Sheet A2 Instructions
A1: * | B1: Main Menu | C1: Exercise
C3: A2 SELECT WITH CRITERIA
C5: What are we doing here?
C6: You're going to love this. It's simple and easy to do.
C7: We're simply going to select cells according to certain criteria,
C8: by using Excel's very own menus!
C10: The most useful applications I've found is getting to formulas quickly
C11: (yes, I know about displaying formulas instead of results in the formula menu),
C12: and finding empty cells.
C14: This is amazing! What if I want to do more?
C15: There are other ways of doing the same thing.
C16: You can do cool stuff with macros of course,
C17: and also by being really good at using find/replace…
... C22: Once you think you understand, go do the most fun exercise!
A25: * | B25: INSTRUCTIONS
B26: Either select a range of cells in which to search, or just don't do anything special to search the entire worksheet.
B27: Go to "Find & Select" in the "Editing" section of the "Home" ribbon and click on "Go To Special". Alternatively, press F5. Click on "Special".
B29: You will be able to select cells according to a specific criteria. Select a criteria and click on "Ok".
B30: Use "Enter" to quickly go from one cell to another.
B31: When cells are all selected like that, you can also apply some formatting to all cells at once if you'd like to do so.
B32: When you're finished, just click anywhere on the worksheet to un-select the cells. See? I wasn't kidding, this is really easy!
B34: In my example, we're selecting all empty cells in range E38 to G43, and then formatting them a bit differently to reveal the hidden smiley face!
A36: * | B36: Selecting blank cells example - Draw a happy face :)
B37: Select cells E41 to I46. Go to Home - Editing section - Find & Select - Go to Special.
B38: Click on "Blanks" and then "Ok". Use the fill tool in the font section of the home ribbon
B39: to apply a background color.
E41: 1 | F41: 2 | G41: 3 | H41: 4 | I41: 5
E42: 6 | G42: 8 | I42: 10
E43: 11 | F43: 12 | G43: 13 | H43: 14 | I43: 15
F44: 17 | G44: 18 | H44: 19
E45: 21 | I45: 25
E46: 26 | F46: 27 | G46: 28 | H46: 29 | I46: 30
A48: * | B48: RESET EXAMPLE
B50: Select cells E50 to I55. Copy. | E50: 1 | F50: 2 | G50: 3 | H50: 4 | I50: 5
B51: Click on cell E41. Paste. | E51: 6 | G51: 8 | I51: 10
E52: 11 | F52: 12 | G52: 13 | H52: 14 | I52: 15
F53: 17 | G53: 18 | H53: 19
E54: 21 | I54: 25
E55: 26 | F55: 27 | G55: 28 | H55: 29 | I55: 30

Sheet A2 Exercise
A3: * | B3: SELECT WITH CRITERIA EXERCISE
B4: Find all the cells with formulas in rows 8 to 14. Practice navigating from one formula to another, and then apply formatting to make the cells with
B5: Formulas pop out. You want the hidden message to be revealed even when the cells are no longer selected.
A7: * | B7: Formulas are hidden below
B8: ="*" -> * | C8: ="*" -> * | D8: ="*" -> * | E8: * | F8: ="*" -> * | G8: * | H8: * | I8: * | J8: ="*" -> * | K8: * | L8: ="*" -> * | M8: ="*" -> * | N8: ="*" -> * | O8: * | P8: ="*" -> * | Q8: ="*" -> * | R8: ="*" -> * | S8: * | T8: ="*" -> * | U8: ="*" -> * | V8: ="*" -> * | W8: * | X8: ="*" -> * | Y8: ="*" -> * | Z8: ="*" -> * | AA8: * | AB8: ="*" -> * | AC8: * | AD8: ="*" -> * | AE8: * | AF8: ="*" -> * | AG8: *
B9: ="*" -> * | C9: * | D9: * | E9: * | F9: * | G9: ="*" -> * | H9: * | I9: ="*" -> * | J9: * | K9: * | L9: ="*" -> * | M9: * | N9: ="*" -> * | O9: * | P9: ="*" -> * | Q9: * | R9: * | S9: * | T9: ="*" -> * | U9: * | V9: ="*" -> * | W9: * | X9: * | Y9: ="*" -> * | Z9: * | AA9: * | AB9: ="*" -> * | AC9: * | AD9: ="*" -> * | AE9: * | AF9: ="*" -> * | AG9: *
B10: ="*" -> * | C10: ="*" -> * | D10: ="*" -> * | E10: * | F10: * | G10: * | H10: ="*" -> * | I10: * | J10: * | K10: * | L10: ="*" -> * | M10: ="*" -> * | N10: ="*" -> * | O10: * | P10: ="*" -> * | Q10: ="*" -> * | R10: ="*" -> * | S10: * | T10: ="*" -> * | U10: ="*" -> * | V10: * | W10: * | X10: * | Y10: ="*" -> * | Z10: * | AA10: * | AB10: ="*" -> * | AC10: * | AD10: ="*" -> * | AE10: * | AF10: ="*" -> * | AG10: *
B11: ="*" -> * | C11: * | D11: * | E11: * | F11: * | G11: ="*" -> * | H11: * | I11: ="*" -> * | J11: * | K11: * | L11: ="*" -> * | M11: * | N11: * | O11: * | P11: ="*" -> * | Q11: * | R11: * | S11: * | T11: ="*" -> * | U11: * | V11: ="*" -> * | W11: * | X11: * | Y11: ="*" -> * | Z11: * | AA11: * | AB11: * | AC11: * | AD11: * | AE11: * | AF11: * | AG11: *
B12: ="*" -> * | C12: ="*" -> * | D12: ="*" -> * | E12: * | F12: ="*" -> * | G12: * | H12: * | I12: * | J12: ="*" -> * | K12: * | L12: ="*" -> * | M12: * | N12: * | O12: * | P12: ="*" -> * | Q12: ="*" -> * | R12: ="*" -> * | S12: * | T12: ="*" -> * | U12: * | V12: * | W12: ="*" -> * | X12: * | Y12: ="*" -> * | Z12: * | AA12: * | AB12: ="*" -> * | AC12: * | AD12: ="*" -> * | AE12: * | AF12: ="*" -> * | AG12: *
B13: * | C13: * | D13: * | E13: * | F13: * | G13: * | H13: * | I13: * | J13: * | K13: * | L13: * | M13: * | N13: * | O13: * | P13: * | Q13: * | R13: * | S13: * | T13: * | U13: * | V13: * | W13: * | X13: * | Y13: * | Z13: * | AA13: * | AB13: * | AC13: * | AD13: * | AE13: * | AF13: * | AG13: *
B14: * | C14: * | D14: * | E14: * | F14: * | G14: * | H14: * | I14: * | J14: * | K14: * | L14: * | M14: * | N14: * | O14: * | P14: * | Q14: * | R14: * | S14: * | T14: * | U14: * | V14: * | W14: * | X14: * | Y14: * | Z14: * | AA14: * | AB14: * | AC14: * | AD14: * | AE14: * | AF14: * | AG14: *

Sheet A3 Instructions
B3: A3 FLASH FILL
B5: What are we doing here?
B6: We're going to use Excel features to magically pull apart or put together text that has a pattern.
B7: You could use flash fill to extract first names from columns containing full names.
B8: You could also use it to combine multiple columns together while ignoring blank cells.
B10: This is amazing! What if I want to do more?
B11: Just keep practicing on your data! It only takes a second to try using flash fill.
B12: You may also want to look into formulas that work with text, such as in sections C1 and C2
B14: How do I get started again?
B15: Just keep reading to learn more about Flash Fill.
B16: Once you feel ready, go do the exercises!
A19: * | B19: Page Menu
B20: Scroll down after selecting item in menu - desired instructions are at the bottom of the screen
B21: How to get Flash Fill to work
B22: What needs to be in place for Flash Fill to work
B23: Important Flash Fill notes
A25: * | B25: INSTRUCTIONS | F25: Top
B26: Review the conditions that need to be in place for Flash Fill to work. | C26: Review here!
B27: Identify a column from which you need to extract data in a pattern, or columns with data that you want to concatenate. [1]
B28: Navigate to the first available blank column next to your data or insert a new blank column. Give your column an exciting title. [2]
B29: Move to the first (top) blank cell in your new blank column. [3]
B30: Manually enter the part of the pattern that you what you want to extract / input. Repeat with the next row. [3]
A32: * | B32: Method 1
B33: Select both rows with content in your "blank" column. [1]
B34: Double-click on the bottom-right of the selection. [2]
B35: Click on the "Auto Fill Options" icon that temporarily appears. [3]
B36: Select "Flash Fill" [4]
A38: * | B38: Method 2
B39: Select the last row in your "blank" column that has content.
B40: Press Ctrl-E on the keyboard (possibly Command-E on the Mac).
A42: * | B42: Both methods
B43: After a few columns, Excel might guess what you're doing and just automatically flash fill the column for you!
B44: If Flash Fill has incorrectly guessed the pattern, or if you have a complex pattern, try manually overwriting incorrect rows with the correct value in a cell or two before working on something else. Flash fill should magically adjust the rest of the column.
A46: * | B46: WHAT NEEDS TO BE IN PLACE FOR FLASH FILL TO WORK | F46: Top
B47: Flash fill only works in Excel 2016+.
B48: Flash fill will fill cells down and/or up a column, not across rows
B49: Your data needs to be organized in a table-like structure, preferably with headers/titles for your columns.
B50: Avoid having completely blank rows. Flash fill should still work if there are some blank cells in a column as long as other cells in the same row have content and no blank needs to go in the column you want to flash fill.
B51: There must be some sort of pattern to your data, a rule that can be used to extract/input the data that is logical and consistent.
A53: * | B53: SUPPLEMENTARY INFORMATION | F53: Top
...

Sheet A3 Exercise
C1: Main Menu | D1: Instructions | T1: Cells in this column and beyond are used for conditional formatting purposes and should be ignored. | AR1: Names | AS1: First Names | AT1: Last names | AU1: Adjective
A3: * | B3: Flash Fill Exercises | AR3: Arden "Awesome" Kayzak
AR4: Sara "Stupendous" Tumpane
A5: * | B5: Page Menu | AR5: Alex "Amazing" Cooper
B6: Scroll down after selecting item in menu - desired instructions are at the bottom of the screen | AR6: Sandra "Superb" Sawchuk
B7: Exercise 1: Random Famous People | AR7: Margaret "Marvelous" Vail
B8: Exercise 2: Random Famous People with Exceptions | AR8: Emanuela "Excellent" Chiriac
B9: Exercise 3: Busy busy airports! | AR9: Giovanna "Great" Badia
B10: Exercise 4: Don't call these numbers! | AR10: Vivek "Valuable" Jadon
B11: Exercise 5: Time travel with months | AR11: Chantal "Clever" Ripp
B12: Demo: Fun with codes
B13: Demo: People and comments
AR14: Amy "Astounding" Paterson
A15: * | B15: Exercise 1: Random Famous People | F15: Top | AR15: Tara "Talented" Stieglitz
AR16: Caleb "Creative" Domsy
B17: Instructions
B18: Use Flash Fill to extract the first name, last name, and adjectives in the random list of famous people.
B20: Example result
B21: Random Famous People | C21: First Name | D21: Last Name | E21: Adjective
B22: Avril 'Awesome' Lavigne | C22: Avril | D22: Lavigne | E22: Awesome
B24: Exercise table
B26: Random Famous People | C26: First Name | D26: Last Name | E26: Adjective | T26: First Name | U26: Last Name | V26: Adjective
B27: Avril 'Awesome' Lavigne | U27: Avril | V27: Lavigne | W27: Awesome
B28: Bryan 'Beautiful' Adams | U28: Bryan | V28: Adams | W28: Beautiful
B29: Celine 'Courageous' Dion | U29: Celine | V29: Dion | W29: Courageous
B30: Leonard 'Lovely' Cohen | U30: Leonard | V30: Cohen | W30: Lovely
B31: Michael 'Magical' Cera | U31: Michael | V31: Cera | W31: Magical
B32: Nathan 'Nice' Filion | U32: Nathan | V32: Filion | W32: Nice
B33: Nelly 'Notable' Furtado | U33: Nelly | V33: Furtado | W33: Notable
B34: Ryan 'Radiant' Gosling | U34: Ryan | V34: Gosling | W34: Radiant
B35: Santa 'Jolly' Claus | U35: Santa | V35: Claus | W35: Jolly
B36: Sarah 'Sensational' MacLachlan | U36: Sarah | V36: MacLachlan | W36: Sensational
B37: Willam 'Winner' Shatner | U37: Willam | V37: Shatner | W37: Winner
A39: * | B39: Exercise 2: Random Famous People with Exceptions | F39: Top
B41: Instructions
B42: Use Flash Fill to extract the adjective and last name, when some famous people don't have an adjective
B44: Example result
B45: Random Famous People | C45: Adj + Last Name
B46: Avril 'Awesome' Lavigne | C46: Awesome Lavigne
B47: Bryan Adams | C47: Adams
...

Sheet A4 Instructions
A1: * | B1: Main Menu | C1: Exercise | D1: Data worksheet
C3: A4 ELIMINATING DUPLICATES
C5: What are we doing here?
C6: We're going to get rid of duplicates to get a list of unique values.
C7: It's really easy, we just have to click lots of stuff in Excel's menu.
C9: This is amazing! What if I want to do more?
C10: Carefully read every single entry in Excel's help file… :D
C12: How do I get started again?
C13: This example is ready to go, just keep reading!
C14: If you need a reset, copy-paste the table at the bottom of this worksheet
C15: Once you think you understand, go do the easiest exercise yet!
A18: * | B18: INSTRUCTIONS
B19: Select the data for which you want to remove duplicates. In Excel's menu, select the "data" ribbon and then "Remove duplicates" from the "Data Tools" section
A21: * | B21: Data table | D21: Steps
A23: * | B23: Remove duplicates across two columns
B25: Count of item | C25: Item | D25: Select cells in the table to the right (B25 to C31)
B26: 1 | C26: Golden ring | D26: Click on the "data" ribbon, and then "Remove duplicates" in the "Data Tools" section.
B27: 1 | C27: Golden ring
B28: 4 | C28: Bears
B29: 2 | C29: Golden ring
B30: 1 | C30: Turtle Dove
B31: 5 | C31: Bears
D32: Make sure that there is a checkmark for "My data has headers" and that both columns are selected.
B33: Reset example (scroll down) | D33: Click "Ok". One duplicate value will be removed.
D34: "Golden ring" is in the list twice because it is paired with "1" in one row, and with "2" in another row.
A36: * | B36: Remove duplicates across one column
B38: Count of item | C38: Item | D38: When you want to find unique values in one column, it's easier to copy-paste it elsewhere.
B39: 1 | C39: Golden ring | D39: But for the sake of this demonstration, select cells in the table to the right (B38 to C44)
B40: 1 | C40: Golden ring | D40: Click on the "data" ribbon, and then "Remove duplicates" in the "Data Tools" section.
B41: 4 | C41: Bears | D41: Excel realizes that there is another column besides this one, but we don't want it.
B42: 2 | C42: Golden ring | D42: Select "Continue with the current selection" and then "Remove duplicates…"
B43: 1 | C43: Turtle Dove | D43: Make sure that there is a checkmark for "My data has headers".
B44: 5 | C44: Bears | D44: Click "Ok". Three duplicate values will be removed.
D45: The "Count of item" column no longer makes sense. Select cells B38 to B44 and delete them.
B46: Reset example (scroll down)
A48: * | B48: SUPPLEMENTARY INFORMATION
A50: * | B50: Conditional formatting
B52: Count of item | C52: Item
B53: 1 | C53: Golden ring
B54: 1 | C54: Golden ring
...

Sheet A4 Exercise
A1: * | B1: Main Menu | C1: Instructions | D1: Data worksheet
A3: * | B3: REMOVE DUPLICATES EXERCISE
B4: Don't worry, this one is REALLY easy. Go copy-paste columns A and B from the 2021 CSD worksheet
B5: into columns G and H of this worksheet. Then remove the duplicates. Easy!
B6: You should find 77 duplicate values, with 19 unique values remaining.
B7: Although sometimes these counts change a bit depending on the copy-paste method you used.
A8: *

Sheet A5 Instructions
A1: * | B1: Main Menu | C1: Exercise
C3: A5 FIND/REPLACE TRICKS
C5: What are we doing here?
C6: You're getting kind of tired, aren't you?
C7: Let's keep it very simple for now. We're… mostly going to look at
C8: some Find/Replace options. You can find text… and replace it with other text.
C10: This is amazing! What if I want to do more?
C11: Try out the options that I haven't covered.
C12: Google "find replace in Excel" to find a few tricks. And "Excel wildcards".
C14: How do I get started again?
C15: Just read the instructions, then go do the exercise.
A18: * | B18: INSTRUCTIONS
B19: You can access find/replace by using the Ctrl-F or Command-F shortcut key, and then clicking on the "replace" tab.
B20: Alternatively, you can click on "Find and select" in the "Edition" section of the "Home" ribbon, and then select "Replace".
B21: Or with a Mac, look at your special editing menu above Excel.
B23: Put in what you want to find in the first text box, and put in what you want to replace it with in the second text box.
B24: Click on options... to get more options.
B26: An interesting but tricky tip is using find/replace to quickly highlight cells that have specific text.
B27: Just click on the "format" button in the "replace by" section, don't input anything in the "replace by" box, and you're free to format the cells
B28: containing the text you're searching for in any way you'd like!
B29: To stop the behavior, click on the "Format" dropdown and select "Clear Replace Format".
B31: You can often clean up data by searching with exact match for cells containing only a space and replacing that with nothing at all.
B32: (Although there are also formulas that serve a similar function.)
B34: You can use * as a wildcard, or ? as a wildcard that only finds one character.
... B37: You can do find/replace for an entire worksheet, for an entire Excel file or only in a specified range of cells.
A39: * | B39: I think that you can go straight to the exercise!

Sheet A5 Exercise
A1: * | B1: Main Menu | C1: Instructions
A3: * | B3: FIND/REPLACE TRICKS EXERCISE
B4: 1 - Using the color of your choice, quickly highlight all cells that have a smiley face. That should be a total of 14 cells.
B5: 2 - Count the number of cells in this worksheet that contain the word face. The answer should be 3 (or 5 if you count instances in this section)
B6: 3 - Count the number of cells that contain the letter "e". The answer should be 11 if you only looked at the below text, 17 if you looked at the entire worksheet.
A8: * | B8: List to use to practice find/replace tricks
B9: I have a smiley face :) | C9: I have a frowny face :( | D9: :) yay yay
B10: It's cold :( | C10: I won the lottery :) | D10: I had to work late. :/
B11: I love chocolate :) | C11: I like cake :) | D11: I don't like ants :(
B12: Smiley faces scare me :( | C12: I'm having fun today :) | D12: :) :) :) :) :) :) :)
B13: I'm helping people with Excel :) | C13: I'm not feeling excellent :( | D13: You wouldn't find any of these cells with an exact match :(

Sheet B1 Instructions
B1: Main Menu | C1: Exercises
C3: B1 XLOOKUP
C5: What are we doing here?
C6: Xlookup... Looks things up for you!
C7: Answer questions like "is x in my main list". Or "I have x in
C8: another spreadsheet but I want it here everywhere it matches?"
C10: This is amazing! What if I want to do more?
C11: Index/Match is similar and helpful if you will be sharing with older versions of Excel.
C13: How do I get started again?
C14: Just read the instructions, then go do the exercises.
A17: * | B17: Page Menu
B18: Scroll down after selecting item in menu - desired instructions are at the bottom of the screen
B19: How to get XLookup to work
B20: What needs to be in place for XLookup to work
B21: Important XLookup notes
B22: XLookup versus VLookup versus Index/Match
A24: * | B24: INSTRUCTIONS | I24: Top
B25: Xlookup will put data in your cell by looking up values in another column. It has six arguments.
B26: First, it needs to know what it will be looking up.
B27: Second, it wants to know the array in which it will be looking up whatever it is you need it to look up.
B28: Third, it wants the "return array" - the columns from which it will be extracting data.
B29: Fourth, it optionally wants to know what it should do if a value it's looking up (in the first part) doesn't exist in the second part.
B30: Fifth, it optionally wants to need if it's looking for an exact match, the closest smaller item, the closest bigger item, or doing a wildcard search.
B31: Sixth, it optionally wants to know if it should be looking from top to bottom, from bottom to top, and whether or not the data has been sorted.
B33: Whenever you're working with ranges or arrays, it's usually a good idea to use the "$" symbols.
B34: Keep in mind that Xlookup never worries about capitalization.
B35: XLookup can get very complex. Start simple, and build complexity in as you get more comfortable!
A37: * | B37: Simple XLookup Example | I37: Top
B38: In the examples below, we have a nice table of sounds that animals make…
B39: …while Farmer Ted has a list of animals for which they would like to automatically associate sounds.
B41: Table of animals and the sounds that they make | E41: Farmer Ted's list of animals | G41: Simple Xlookup
B42: Animals | C42: Sounds | E42: Animal Names | F42: Animals | G42: Sounds
B43: Cat | C43: Miow | E43: Felix | F43: Cat | G43: =_xlfn.XLOOKUP(F43,$B$43:$B$49,$C$43:$C$49,"NOT FOUND!!!") -> Miow
B44: Giraffe | C44: ??? | E44: Spot | F44: Dog | G44: =_xlfn.XLOOKUP(F44,$B$43:$B$49,$C$43:$C$49,"NOT FOUND!!!") -> Woof
B45: Cricket | C45: Cricket cricket | E45: Hortense | F45: Giraffe | G45: =_xlfn.XLOOKUP(F45,$B$43:$B$49,$C$43:$C$49,"NOT FOUND!!!") -> ???
B46: Cow | C46: Mooo | E46: Rover | F46: Dog | G46: =_xlfn.XLOOKUP(F46,$B$43:$B$49,$C$43:$C$49,"NOT FOUND!!!") -> Woof
B47: Pig | C47: Oink oink | E47: Bacon | F47: Pig | G47: =_xlfn.XLOOKUP(F47,$B$43:$B$49,$C$43:$C$49,"NOT FOUND!!!") -> Oink oink
B48: Duck | C48: Quack quack | E48: Donald | F48: Duck | G48: =_xlfn.XLOOKUP(F48,$B$43:$B$49,$C$43:$C$49,"NOT FOUND!!!") -> Quack quack
B49: Dog | C49: Woof | E49: Jimmy | F49: Cricket | G49: =_xlfn.XLOOKUP(F49,$B$43:$B$49,$C$43:$C$49,"NOT FOUND!!!") -> Cricket cricket
E50: Barbecued | F50: Pig | G50: =_xlfn.XLOOKUP(F50,$B$43:$B$49,$C$43:$C$49,"NOT FOUND!!!") -> Oink oink
...

Sheet B1 Exercise
B1: Main Menu | C1: Instructions
B3: XLookup Exercises
A5: * | B5: Page Menu
B6: Scroll down after selecting item in menu - desired instructions are at the bottom of the screen
B7: Exercise 1: Just like your "How To" notes!
B8: Exercise 2: Celebrities and cities
B9: Exercise 3: Superhero equipment is expensive!
B10: Exercise 4: You can count on movies!
B11: Exercise 5: Comparing apples and oranges
B12: Demo: A magical dropdown
B14: Exercise 1: Just like in your "How To" notes! | I14: Top
B16: Instructions
B17: Farmer Ted has acquired a few new animals. Help them identify the sounds their animals make.
B18: Use XLookup identify sounds in column G. If an animal doesn't exist, put in a blank ("")
B20: Table with values to look up | E20: Your table with values to find
B21: Animals | C21: Sounds | E21: Animal Name | F21: Type of Animal | G21: Look up the sound
B22: Bird | C22: Tweet Tweet | E22: Bacon | F22: Pig | T22: Oink oink
B23: Cat | C23: Miow | E23: Big | F23: Bird | T23: Tweet Tweet
B24: Cow | C24: Mooo | E24: Chops | F24: Pig | T24: Oink oink
B25: Cricket | C25: Cricket cricket | E25: Donald | F25: Duck | T25: Quack quack
B26: Dog | C26: Woof | E26: Felix | F26: Cat | T26: Miow
B27: Duck | C27: Quack quack | E27: Hortense | F27: Giraffe | T27: ???
B28: Giraffe | C28: ??? | E28: Jimmy | F28: Cricket | T28: Cricket cricket
B29: Kangaroo | C29: Who knows? | E29: Later | F29: Gator
B30: Pig | C30: Oink oink | E30: Rover | F30: Dog | T30: Woof
E31: Spot | F31: Dog | T31: Woof
E32: Sprinkles | F32: Cat | T32: Miow
E33: Tournedos | F33: Pig | T33: Oink oink
E34: Tweety | F34: Bird | T34: Tweet Tweet
B37: Exercise 2: Celebrities and cities | I37: Top
B39: Instructions
B40: You've been compiling a list of famous people, the city and country they come from, and how the average temperature of that city had an impact on their career.
B41: However, you're a busy person! You can't be expected to type up the country and the temperature each time you put in the name of the city.
B42: So to speed things up here, use Xlookup to find the appropriate country in column H, and magically load the status/temperature in column I.
B44: Table with values to look up | F44: Your table with values to find
B45: City | C45: Country | D45: Status | F45: Celebrities | G45: City of origin | H45: Look up the country | I45: Look up the status
B46: Moncton | C46: Canada | D46: Cold and wet | F46: Atwood, Margaret | G46: Ottawa | T46: Canada | U46: Cold
B47: Ottawa | C47: Canada | D47: Cold | F47: Bastarache, Michel | G47: Moncton | T47: Canada | U47: Cold and wet
B48: Winnipeg | C48: Canada | D48: Colder | F48: Claus, Santa | G48: Christmas Village | T48: North Pole | U48: Magical
B49: Honolulu | C49: Hawaii | D49: Nice and warm | F49: Fox, Terry | G49: Winnipeg | T49: Canada | U49: Colder
...

Sheet B2 Instructions
A1: * | B1: Main Menu | C1: Exercise
C3: B2 OR, AND, IF, and IFS
C5: What are we doing here?
C6: We're looking at some logic formulas.
C7: IF and IFS which lets you return what you want according to a criteria.
C8: AND which checks if one or more criteria are all true.
C9: OR which checks if at least one criteria is true.
C11: This is amazing! What if I want to do more?
C12: I don't know? Maybe look up boolean operators?
C13: A lot of what we do here is boolean logic.
C14: And definitely look up TRIM, and UPPER and LOWER.
C16: How do I get started again?
C17: This example is ready to go, just keep reading!
... C19: Once you think you understand, go do the exercise!
A22: * | B22: INSTRUCTIONS
B23: The IF formula takes a criteria, usually in the form of a comparison such as if a cell is equal, or bigger, or smaller than a given value.
B24: The next two arguments are optional but I recommend always entering them. They let you decide what is returned by the IF formula.
B25: A value if the criteria is true, or a value if the criteria is false.
B27: The IFS formula takes a criteria, than it needs to know what to return if that criteria is true.
B28: Rinse and repeat for all your criteria. It stops its work once it finds that something is true.
B29: As the last two arguments, you can put in TRUE followed by what the IFS formula should return if nothing else in the list of conditions was true.
B31: The AND and OR formulas return "True" or "False".
B32: The AND formula requires that ALL criteria be met in order for the formula to return "TRUE".
B33: The OR formula requires that at least one of the criteria be met in order for the formula to return "TRUE".
B35: You can have the IF formula return a blank by entering "" as the value if true or false,
B36: and a number like 0 or 1 by simply putting in the number without quotation marks.
B37: And you can use an AND or OR formula within an IF formula.
A39: * | B39: Scariness table and criteria | H39: Formulas
A41: * | B41: Simple IF example
B42: Let's flag all the cases where the scariness is 5 or more.
B44: Horror source | C44: Nature | D44: Scariness (out of 10) | E44: Amount | F44: Distance (km) | H44: Simple IF formula
B45: Bermuda Triangle | C45: Phenomenon | D45: 5 | E45: 1 | F45: 2290 | H45: =IF(D45>=5,"I AM CONCERNED", "NOTHING TO SEE HERE") -> I AM CONCERNED | I45: =IF(D45>=5,"I AM CONCERNED", "NOTHING TO SEE HERE")
B46: Vampires | C46: Monster | D46: 4 | E46: 0 | F46: 10 | H46: =IF(D46>=5,"I AM CONCERNED", "NOTHING TO SEE HERE") -> NOTHING TO SEE HERE
B47: Zombies | C47: Monster | D47: 9 | E47: 0 | F47: 10 | H47: =IF(D47>=5,"I AM CONCERNED", "NOTHING TO SEE HERE") -> I AM CONCERNED
B48: Germs | C48: Natural | D48: 5 | E48: 100000000 | F48: 1 | H48: =IF(D48>=5,"I AM CONCERNED", "NOTHING TO SEE HERE") -> I AM CONCERNED
B49: Unfulfillment | C49: Philosophical | D49: 10 | E49: 0 | F49: 0 | H49: =IF(D49>=5,"I AM CONCERNED", "NOTHING TO SEE HERE") -> I AM CONCERNED
B50: Noises | C50: Phenomenon | D50: 1 | E50: 12 | F50: 0 | H50: =IF(D50>=5,"I AM CONCERNED", "NOTHING TO SEE HERE") -> NOTHING TO SEE HERE
B51: Loch Ness Monster | C51: Monster | D51: 3 | E51: 1 | F51: 4218 | H51: =IF(D51>=5,"I AM CONCERNED", "NOTHING TO SEE HERE") -> NOTHING TO SEE HERE
B53: It might be best to assign a cell for the criteria - what if we change our minds about how much scariness we can tolerate?
B54: Scariness criteria | C54: 5 | D54: <- Try changing this number and see what happens in the "Simple worry" column of the below table.
...

Sheet B2 Exercise
A1: * | B1: Main Menu | C1: Instructions
A3: * | B3: IF, AND, and OR EXERCISE
B4: You are worried about the various threats that surround you at all times.
B5: Use a combination of the IF and AND formulas to flag cases with "BE VERY WORRIED" in column H (Big Worry)
B6: where the scariness is at least 5, the amount of a thing is at least 1, and the distance is 10 or lower.
B8: Then, flag cases with "Maybe worry" in column I (Small Worry) where the scariness is at least 8,
B9: or where the amount is higher or equal to 50, or the distance is 10 or lower.
A10: * | B10: Criteria
C11: Scariness of at least | E11: Amount of at least | G11: Distance of no more than
B12: Big worry | C12: 5 | D12: and | E12: 1 | F12: and | G12: 10
B13: Small worry | C13: 8 | D13: or | E13: 50 | F13: or | G13: 10
A15: * | B15: Table of threats | H15: Tables of worries by criteria
B16: Horror source | C16: Nature | D16: Scariness (out of 10) | E16: Amount | F16: Distance (km) | H16: Big Worry | I16: Small Worry
B17: Bermuda Triangle | C17: Phenomenon | D17: 5 | E17: 1 | F17: 2290
B18: Vampires | C18: Monster | D18: 4 | E18: 0 | F18: 10 | J18: <-
B19: Zombies | C19: Monster | D19: 9 | E19: 0 | F19: 10 | J19: <-
B20: Germs | C20: Natural | D20: 5 | E20: 100000000 | F20: 1 | G20: -> | J20: <-
B21: Unfulfillment | C21: Philosophical | D21: 10 | E21: 0 | F21: 0 | J21: <-
B22: Noises | C22: Phenomenon | D22: 1 | E22: 12 | F22: 0 | J22: <-
B23: Loch Ness Monster | C23: Monster | D23: 3 | E23: 1 | F23: 4218
A25: * | B25: IFS exercise
B26: You are worried about the various threats that surround you at all times and find natural threats particularly scary
B27: Use the IFS formula to identify any threat that is natural in nature as "SO SCARY".
B28: Identify any other threat of 6 or more as "ALSO SCARY".
B29: And anything else as "This is fine!".
A30: * | B30: Criteria
B31: Condition | C31: Value | D31: Result
B32: If nature of threat is.. | C32: Natural | D32: SO SCARY
B33: Scariness equal to or more than | C33: 6 | D33: ALSO SCARY
B34: Anything else | D34: This is fine!
A36: * | B36: Table of threats | H36: Table of worries by criteria
B37: Horror source | C37: Nature | D37: Scariness (out of 10) | E37: Amount | F37: Distance (km) | H37: How scary is this?
B38: Bermuda Triangle | C38: Phenomenon | D38: 5 | E38: 1 | F38: 2290
B39: Vampires | C39: Monster | D39: 4 | E39: 0 | F39: 10
B40: Zombies | C40: Monster | D40: 9 | E40: 0 | F40: 10 | I40: <-
B41: Germs | C41: Natural | D41: 5 | E41: 100000000 | F41: 1 | G41: ->
B42: Unfulfillment | C42: Philosophical | D42: 10 | E42: 0 | F42: 0 | I42: <-
B43: Noises | C43: Phenomenon | D43: 1 | E43: 12 | F43: 0
B44: Loch Ness Monster | C44: Monster | D44: 3 | E44: 1 | F44: 4218

Sheet B3 Instructions
A1: * | B1: Main Menu
C3: B3 COUNTA
C5: What are we doing here?
C6: We're going to take a look at CountA.
C7: It counts the number of non-blank value. So easy! No need to even practice!
C9: This is amazing! What if I want to do more?
C10: Google countA, I guess? Or look at the different kinds of counts.
C12: How do I get started again?
C13: This example is ready to go, just keep reading!
A16: * | B16: INSTRUCTIONS
B17: CountA just counts the number of non-blanks. That's it. Short and sweet! Great for data quality control.
A19: * | B19: CountA example
B20: I have | C20: Two blanks | D20: Everything
D21: is good
B22: a blank | D22: no blanks
B23: four rows | C23: Three rows | D23: Five rows
B24: with data | C24: with data | D24: with data
B26: =COUNTA(B20:B24) | C26: =COUNTA(C20:C24) | D26: =COUNTA(D20:D24)
B27: =COUNTA(B20:B24) -> 4 | C27: =COUNTA(C20:C24) -> 3 | D27: =COUNTA(D20:D24) -> 5
A29: * | B29: SUPPLEMENTARY INFORMATION
A31: * | B31: Spaces
B33: If CountA is returning a number higher than you were expecting, it could be that one of the cells contains a space instead of a blank.
B34: Try using find/replace (see A5) and matching the whole cell content to find spaces and replacing them with nothing.
B36: There is
B38: a space in B37
B39: so it's counting
B40: 5 non-blank rows
B42: =COUNTA(B36:B40)
B43: =COUNTA(B36:B40) -> 5

Sheet B4 Instructions
A1: * | B1: Main Menu | C1: Exercise | D1: Data worksheet
C3: B4 SUMIF AND SUMIFS
C5: What are we doing here?
C6: We're going to learn about SumIF and SumIFs.
C7: These let us use criteria in order to add numbers.
C9: This is amazing! What if I want to do more?
C10: I'm not sure! Maybe learn about CSE formulas in 2_2?
C12: How do I get started again?
C13: This example is ready to go, just keep reading!
C14: Once you think you understand, go do the exercise!
A17: * | B17: INSTRUCTIONS
B18: Both SumIF and SumIFs use ranges, and you're going to want to use the $ symbol for those so that the ranges will stay the same no matter where you
B19: move in the worksheet.
B21: SumIF has three arguments. First, give it the range of cells in which it is going to lookup a value that will fulfill your desired criteria.
B22: Next, give it your criteria so that it can search in the provided range and see if anything fits your criteria.
B23: Lastly, tell it what it is adding up.
B25: SumIFs needs at least three arguments. First, give it the range of cells that it is going to add.
B26: Next, give it the range where you are going to check a criteria.
B27: Lastly, tell it what criteria it needs to check.
B28: You can repeat the second and third steps for other criteria to check IN OTHER COLUMNS. SumIFs does not understand 'OR' logic, you can't check
B29: for more than one criteria in a same column (or at least, not without involving brain breaking arrays or adding SumIFs together).
A31: * | B31: SumIF Example
A33: * | B33: Tool cost table
B34: Status | C34: Name | D34: Tool | E34: Cost | F34: <- Try changing the costs and
B35: Hero | C35: Peter Parker | D35: Web Slinger | E35: 24.85 | F35: see what happens to the totals below
B36: Hero | C36: Bruce Wayne | D36: Bat car | E36: 125030
B37: Villain | C37: Dr. Horrible | D37: Freeze Ray | E37: 350000
B38: Hero | C38: Peter Parker | D38: Venom antidote | E38: 55.82
B39: Ambiguous | C39: Dentists | D39: Scary looking equipment | E39: 552.25
A41: * | B41: ="Adding up the cost of tools for everyone with a " &B44& " status!" -> Adding up the cost of tools for everyone with a Hero status!
B42: Try changing "Hero" to "Villain" or "Ambiguous" and see what happens!
B43: Criteria | C43: Sum of cost of tools | D43: Text of formula
B44: Hero | C44: =SUMIF($B$35:$B$39,B44,$E$35:$E$39) -> 125110.67 | D44: =SUMIF($B$35:$B$39,B44,$E$35:$E$39)
A46: * | B46: ="Adding up the cost of tools for everyone who is a "&B49&" OR " &B50 & " - 2 possibilities in a same column!" -> Adding up the cost of tools for everyone who is a Hero OR Ambiguous - 2 possibilities in a same column!
B47: Try changing the criteria in the first column and see what happens!
B48: Criteria | C48: Sum of cost of tools | D48: Text of formula
B49: Hero | C49: =SUMIF($B$35:$B$39,B49,$E$35:$E$39)+SUMIF($B$35:$B$39,B50,$E$35:$E$39) -> 125662.92 | D49: =SUMIF($B$35:$B$39,B49,$E$35:$E$39)+SUMIF($B$35:$B$39,B50,$E$35:$E$39)
B50: Ambiguous
A52: * | B52: SumIFs Example
A54: * | B54: Coolness and annual salary table
...

Sheet B4 Exercise
A1: * | B1: Main Menu | C1: Instructions | D1: Data worksheet | I1: CD | J1: SUB | K1: SUBDIV Name | L1: Tot Pop 2021 | N1: Unique CD
I2: 5 | J2: 1 | K2: Barrington | L2: 6523 | N2: 5
A3: * | B3: SUMIF AND SUMIFS EXERCISE | I3: 1 | J3: 4 | K3: Clark's Harbour | L3: 725 | N3: 1
B4: We're going to estimate the total population (contained in column E of the 2021 CSD worksheet) for each census division in NS. | I4: 1 | J4: 6 | K4: Shelburne | L4: 4336 | N4: 2
B5: You'll notice that census divisions appear more than once in the 2021 CSD worksheet. | I5: 1 | J5: 8 | K5: Shelburne | L5: 1644 | N5: 3
I6: 1 | J6: 9 | K6: Lockeport | L6: 476 | N6: 4
B7: First of all, I've prepared a lot of things for you, using concepts we've already covered: | I7: 2 | J7: 1 | K7: Argyle | L7: 7870 | N7: 6
B8: 1 - I've copied columns B, C, D and E of the 2021 CSD worksheet into columns H, I, J, and K of this worksheet. | I8: 2 | J8: 4 | K8: Yarmouth | L8: 10067 | N8: 7
B9: 2 - I changed a "1" CD to a "5" (in H2) for the purposes of making sure that you are using absolute addresses in your ranges | I9: 2 | J9: 6 | K9: Yarmouth | L9: 6829 | N9: 8
B10: and to illustrate that content in columns does not need to be in order... | I10: 2 | J10: 40 | K10: Yarmouth 33 | L10: 181 | N10: 9
B11: 3 - I've copied-pasted column H into column M. | I11: 3 | J11: 1 | K11: Clare | L11: 7678 | N11: 10
B12: 4 - I removed duplicates from column M. | I12: 3 | J12: 4 | K12: Digby | L12: 7242 | N12: 11
B13: 5 - I copy-pasted column M into the exercise's column B below. | I13: 3 | J13: 6 | K13: Digby | L13: 2001 | N13: 12
I14: 3 | J14: 9 | K14: Bear River (Part) 6 | L14: 141 | N14: 13
B15: Now, I trust YOU to enter a formula in column C that will use SumIF and the values in column B to find the total population | I15: 4 | J15: 1 | K15: Medway River 11 | L15: 15 | N15: 14
B16: (column K) by census division according to the 2021 CSD worksheet. And do the same in column D for SumIFs. | I16: 4 | J16: 9 | K16: Ponhook Lake 10 | L16: 15 | N16: 15
B17: There are 96 rows in column I: row 1 has the header, and rows 2 to 96 contain data. | I17: 4 | J17: 10 | K17: Queens | L17: 10422 | N17: 16
I18: 4 | J18: 15 | K18: Wildcat 12 | L18: 49 | N18: 17
A19: * | B19: Table to use to practice SumIF and SumIFs | G19: Did it work? | I19: 5 | J19: 1 | K19: Annapolis, Subd. D | L19: 3049 | N19: 18
B20: Census Division | C20: SumIf TotPop | D20: SumIfs TotPop | E20: Expected result | G20: Success? | I20: 5 | J20: 2 | K20: Bear River (Part) 6 | L20: 0
B21: 1 | E21: 7181 | G21: =IF(AND(E21=C21, E21=D21),"WOOHOO!","Not yet…") -> Not yet… | I21: 5 | J21: 4 | K21: Annapolis, Subd. A | L21: 5980
B22: 2 | E22: 24947 | G22: =IF(AND(E22=C22, E22=D22),"WOOHOO!","Not yet…") -> Not yet… | I22: 5 | J22: 6 | K22: Bear River 6B | L22: 15
B23: 3 | E23: 17062 | G23: =IF(AND(E23=C23, E23=D23),"WOOHOO!","Not yet…") -> Not yet… | I23: 5 | J23: 8 | K23: Annapolis Royal | L23: 530
B24: 4 | E24: 10501 | G24: =IF(AND(E24=C24, E24=D24),"WOOHOO!","Not yet…") -> Not yet… | I24: 5 | J24: 9 | K24: Annapolis, Subd. B | L24: 4587
B25: 5 | E25: 27775 | G25: =IF(AND(E25=C25, E25=D25),"WOOHOO!","Not yet…") -> Not yet… | I25: 5 | J25: 14 | K25: Annapolis, Subd. C | L25: 5218
B26: 6 | E26: 48599 | G26: =IF(AND(E26=C26, E26=D26),"WOOHOO!","Not yet…") -> Not yet… | I26: 5 | J26: 16 | K26: Middleton | L26: 1873
B27: 7 | E27: 62914 | G27: =IF(AND(E27=C27, E27=D27),"WOOHOO!","Not yet…") -> Not yet… | I27: 6 | J27: 1 | K27: Lunenburg | L27: 25545
B28: 8 | E28: 45140 | G28: =IF(AND(E28=C28, E28=D28),"WOOHOO!","Not yet…") -> Not yet… | I28: 6 | J28: 4 | K28: Bridgewater | L28: 8790
B29: 9 | E29: 440072 | G29: =IF(AND(E29=C29, E29=D29),"WOOHOO!","Not yet…") -> Not yet… | I29: 6 | J29: 6 | K29: Lunenburg | L29: 2396
B30: 10 | E30: 51476 | G30: =IF(AND(E30=C30, E30=D30),"WOOHOO!","Not yet…") -> Not yet… | I30: 6 | J30: 8 | K30: Mahone Bay | L30: 1064
B31: 11 | E31: 30538 | G31: =IF(AND(E31=C31, E31=D31),"WOOHOO!","Not yet…") -> Not yet… | I31: 6 | J31: 9 | K31: Chester | L31: 10693
B32: 12 | E32: 43657 | G32: =IF(AND(E32=C32, E32=D32),"WOOHOO!","Not yet…") -> Not yet… | I32: 6 | J32: 11 | K32: Gold River 21 | L32: 81
... B38: 18 | E38: 7441 | G38: =IF(AND(E38=C38, E38=D38),"WOOHOO!","Not yet…") -> Not yet… | I38: 7 | J38: 12 | K38: Kentville | L38: 6630
I39: 7 | J39: 2 | K39: Annapolis Valley First Nation | L39: 743
I40: 7 | J40: 16 | K40: Kings, Subd. B | L40: 11951
I41: 7 | J41: 21 | K41: Kings, Subd. D | L41: 5264
I42: 7 | J42: 24 | K42: Wolfville | L42: 5057
I43: 7 | J43: 27 | K43: Glooscap 35 | L43: 111
I44: 8 | J44: 3 | K44: West Hants | L44: 19509
I45: 8 | J45: 8 | K45: East Hants | L45: 22892
...

Sheet C1 Instructions
A1: * | B1: Main Menu | C1: Exercise | D1: Data worksheet
C3: C1 CONCATENATION
C5: What are we doing here?
C6: We're going to use & to concatenate some strings/text
C8: This is amazing! What if I want to learn more?
C9: Just Google "Excel string functions"
C11: How do I get started again?
C12: This example is ready to go, just keep reading!
C13: Once you think you understand, go do the exercise!
A16: * | B16: INSTRUCTIONS
B17: Use the & operator to concatenate text, just like you would use + or - to add or substract numbers. Use the address of a cell to concatenate its contents.
B18: If the cell contains a number, it will be converted to text. Use "" to insert text.
B19: Use """ to insert the " symbol, look carefully at the formula that results. (In macros, we use "" for some reason, but you don't need to know that right now)
B20: Notice that only the result displayed by cells with formulas is concatenated, not the formula itself.
A22: * | B22: Data | C22: Formulas using data
A24: * | B24: Let's concatenate the content of cells B25 to B29
B25: Use & to concatenate. | C25: =B25&B26&B27&B28&B29
B26: Use the address of a cell to concatenate it. | C26: =B25&B26&B27&B28&B29 -> Use & to concatenate.Use the address of a cell to concatenate it.If the cell contains a number, it will be converted to text.26is a number.
B27: If the cell contains a number, it will be converted to text.
B28: 26
B29: is a number.
A31: * | B31: Let's insert some text and spaces to the content of cells B32 and B33
B32: Use "" to insert text. | C32: ="Text inserted. "&B32&" "&B33
B33: Wow there are spaces! | C33: ="Text inserted. "&B32&" "&B33 -> Text inserted. Use "" to insert text. Wow there are spaces!
A35: * | B35: Let's insert "Wow!" and the contents of B36 and B37
B36: Use """ to insert the " symbol, | C36: ="""Wow!"" "&B36&B37
B37: look carefully at the resulting formula | C37: ="""Wow!"" "&B36&B37 -> "Wow!" Use """ to insert the " symbol, look carefully at the resulting formula
A39: * | B39: Let's insert C37 and the contents of B41
C40: =B41&" "&C37
B41: Notice that the content displayed by cells with formulas is concatenated, not the formula itself. | C41: =B41&" "&C37 -> Notice that the content displayed by cells with formulas is concatenated, not the formula itself. "Wow!" Use """ to insert the " symbol, look carefully at the resulting formula
A43: * | B43: SUPPLEMENTARY INFORMATION
A45: * | B45: Recent versions of Excel will allow you to use the TEXTJOIN formula to concatenate text strings with a delimiter
B46: Use & to concatenate. | C46: =TEXTJOIN(" ",TRUE,B46:B47)
B47: Use the address of a cell to concatenate it. | C47: =_xlfn.TEXTJOIN(" ",TRUE,B46:B47) -> Use & to concatenate. Use the address of a cell to concatenate it.
B49: If cell C47 doesn't seem to display the concatenated version of B45 and B46 with a text in between, you might not have the right version of Excel.
B50: TEXTOIN is a great option when everything needs to be concatenated with the same delimiter.
A52: * | B52: Recent versions of Excel will allow you to use the CONCAT formula to concatenate text strings
B53: Use & to concatenate. | C53: =CONCAT(B53:B54)
B54: Use the address of a cell to concatenate it. | C54: =_xlfn.CONCAT(B53:B54) -> Use & to concatenate.Use the address of a cell to concatenate it.
B56: This is very similar to using the & symbol to concatenate.
...

Sheet C1 Exercise
A1: * | B1: Main Menu | C1: Instructions | D1: Data worksheet
A3: * | B3: CONCATENATION EXERCISE
B4: The 2021 CSD worksheet contains Nova Scotia data from the 2021 census. You get confused when you try to make sense of the geography, so you
B5: decide you want to create a single column containing the abbreviation "NS", the number of the census division (CD column), and the number of
B6: the subdivision (SUBDIV column) separated by a "-" . Use concatenation in order to achieve this. See the expected results column to get an idea
B7: of what your concatenated string should look like.
B9: You don't need to transfer any data to this worksheet in order for the concatenation to work. You can just select the cell in the other worksheet
B10: when typing in your formula, or reference it using the provided example. But I'm in a good mood, so I've gone ahead and copied the data over to
B11: this worksheet in columns E and F
A13: * | B13: Referencing cell A2 in the 2021 CSD worksheet
A15: * | B15: Typing in | C15: Results in the number
B16: ='2021 CSD'!A2 | C16: ='2021 CSD'!A2 -> 12
A18: * | B18: Table to use to practice concatenation | H18: Did it work?
A19: * | B19: Row in 2021 CSD | C19: Insert your formula in this column | D19: Expected result | E19: CD | F19: SUBDIV | H19: Success?
B20: 2 | D20: NS 1-1 | E20: 1 | F20: 1 | H20: =IF(D20=C20,"YAY!","Not yet...") -> Not yet...
B21: 3 | D21: NS 1-4 | E21: 1 | F21: 4 | H21: =IF(D21=C21,"YAY!","Not yet...") -> Not yet...
B22: 4 | D22: NS 1-6 | E22: 1 | F22: 6 | H22: =IF(D22=C22,"YAY!","Not yet...") -> Not yet...
B23: 5 | D23: NS 1-8 | E23: 1 | F23: 8 | H23: =IF(D23=C23,"YAY!","Not yet...") -> Not yet...
B24: 6 | D24: NS 1-9 | E24: 1 | F24: 9 | H24: =IF(D24=C24,"YAY!","Not yet...") -> Not yet...
B25: 7 | D25: NS 2-1 | E25: 2 | F25: 1 | H25: =IF(D25=C25,"YAY!","Not yet...") -> Not yet...
B26: 8 | D26: NS 2-4 | E26: 2 | F26: 4 | H26: =IF(D26=C26,"YAY!","Not yet...") -> Not yet...
B27: 9 | D27: NS 2-6 | E27: 2 | F27: 6 | H27: =IF(D27=C27,"YAY!","Not yet...") -> Not yet...
B28: 10 | D28: NS 2-40 | E28: 2 | F28: 40 | H28: =IF(D28=C28,"YAY!","Not yet...") -> Not yet...
B29: 11 | D29: NS 3-1 | E29: 3 | F29: 1 | H29: =IF(D29=C29,"YAY!","Not yet...") -> Not yet...
B30: 12 | D30: NS 3-4 | E30: 3 | F30: 4 | H30: =IF(D30=C30,"YAY!","Not yet...") -> Not yet...
B31: 13 | D31: NS 3-6 | E31: 3 | F31: 6 | H31: =IF(D31=C31,"YAY!","Not yet...") -> Not yet...
B32: 14 | D32: NS 3-9 | E32: 3 | F32: 9 | H32: =IF(D32=C32,"YAY!","Not yet...") -> Not yet...

Sheet C2 Instructions
A1: * | B1: Main Menu | C1: Exercise | D1: Data worksheet
C3: C2 LEFT, RIGHT, MID, and FIND STRING FUNCTIONS
C5: What are we doing here?
C6: We're going to extract parts of the text contained in a cell.
C7: This is REALLY useful!
C9: This is amazing! What if I want to do more?
C10: Just Google "Excel string functions"
C12: How do I get started again?
C13: This example is ready to go, just keep reading!
C14: Once you think you understand, go do the exercise!
A17: * | B17: INSTRUCTIONS
B18: The LEFT function will extract a specified number of characters starting from the left of a string. Don't worry, both text and numbers can be manipulated as strings.
B19: The RIGHT function does the same thing, but it starts from the right.
B20: The MID function lets you extract a specified number of characters, starting from a specified location.
B21: The FIND function will try to find a character, and give you the number of its position in a string. We use it to do MAGIC!
A23: * | B23: Data | C23: Lets use LEFT to extract the province | D23: Let's use RIGHT to extract the last number
C24: =LEFT(B25,2) | D24: =RIGHT(B25,1)
B25: NS 1-8 | C25: =LEFT(B25,2) -> NS | D25: =RIGHT(B25,1) -> 8
B26: NS 2-4 | C26: =LEFT(B26,2) -> NS | D26: =RIGHT(B26,1) -> 4
B27: NS 2-40 | C27: =LEFT(B27,2) -> NS | D27: =RIGHT(B27,1) -> 0
B28: NS 3-1 | C28: =LEFT(B28,2) -> NS | D28: =RIGHT(B28,1) -> 1
B29: NS 3-9 | C29: =LEFT(B29,2) -> NS | D29: =RIGHT(B29,1) -> 9
B30: NS 4-10 | C30: =LEFT(B30,2) -> NS | D30: =RIGHT(B30,1) -> 0
B31: QC 26-3 | C31: =LEFT(B31,2) -> QC | D31: =RIGHT(B31,1) -> 3
B32: ON 8-446 | C32: =LEFT(B32,2) -> ON | D32: =RIGHT(B32,1) -> 6
A34: * | B34: Data | C34: Let's use MID to grab the 3 characters following the space | D34: Let's see what FIND does when we search for "-"
C35: =MID(B36,4,3) | D35: =FIND("-",B36) | E35: Counting from the left, that's the number of characters until we get to "-"
B36: NS 1-8 | C36: =MID(B36,4,3) -> 1-8 | D36: =FIND("-",B36) -> 5
B37: NS 2-4 | C37: =MID(B37,4,3) -> 2-4 | D37: =FIND("-",B37) -> 5
B38: NS 2-40 | C38: =MID(B38,4,3) -> 2-4 | D38: =FIND("-",B38) -> 5
B39: NS 3-1 | C39: =MID(B39,4,3) -> 3-1 | D39: =FIND("-",B39) -> 5
B40: NS 3-9 | C40: =MID(B40,4,3) -> 3-9 | D40: =FIND("-",B40) -> 5
B41: NS 4-10 | C41: =MID(B41,4,3) -> 4-1 | D41: =FIND("-",B41) -> 5
B42: QC 26-3 | C42: =MID(B42,4,3) -> 26- | D42: =FIND("-",B42) -> 6
B43: ON 8-446 | C43: =MID(B43,4,3) -> 8-4 | D43: =FIND("-",B43) -> 5
A45: * | B45: Data | C45: Let's use MID and FIND to grab the number in the middle | D45: Let's use RIGHT and FIND to grab the number on the right
C46: =MID(B47,4,(FIND("-",B47)-4)) | D46: =RIGHT(B47,(LEN(B47)-FIND("-",B47))) | E46: LEN gives you the total number of characters in a string, by the way.
B47: NS 1-8 | C47: =MID(B47,4,(FIND("-",B47)-4)) -> 1 | D47: =RIGHT(B47,(LEN(B47)-FIND("-",B47))) -> 8 | E47: Congrats on finding the hidden bonus function!
B48: NS 2-4 | C48: =MID(B48,4,(FIND("-",B48)-4)) -> 2 | D48: =RIGHT(B48,(LEN(B48)-FIND("-",B48))) -> 4
B49: NS 2-40 | C49: =MID(B49,4,(FIND("-",B49)-4)) -> 2 | D49: =RIGHT(B49,(LEN(B49)-FIND("-",B49))) -> 40
...

Sheet C2 Exercise
A1: * | B1: Main Menu | C1: Instructions | D1: Data worksheet
A3: * | B3: LEFT, RIGHT, MID, FIND, LEN EXERCISE
B4: This exercise is harder than it looks, but I believe in you!
B5: Scroll down and look at that list of names.
B6: Figure out a way to extract the first name and the last name using a formula.
B7: Now you'll be able to alphabetize the list by last name!
A9: * | B9: Table with names to extract | F9: Example of a list sorted by last name
B10: Names | C10: First Name | D10: Last Name | F10: Do the exercise and ordering by last name becomes very easy to do!
B11: Barbara Gordon | F11: Brown Stephanie
B12: Bruce Wayne | F12: Cain Cassandra
B13: Cassandra Cain | F13: Drake Tim
